Workbook

Sheet README
A1: ChopDot Financial Model (2026 Baseline)
A2: Purpose | B2: Editable 5-year operating model for ChopDot today vs tomorrow planning.
A3: How to use | B3: Change blue input cells on the Assumptions sheet. Excel/Sheets will recalculate formulas.
A4: What this model covers | B4: Current run costs, customer pricing, revenue model, 5-year P&L, runway, and implied valuation scenarios.
A5: What this model does not do | B5: It does not provide legal advice, debt modeling, taxes by jurisdiction, or guaranteed fundraising/valuation outcomes.
A6: Key principle | B6: Today = coordination + proof software. Tomorrow = modular commitment infrastructure.
A7: Launch posture | B7: Non-custodial, no yield, no pooled funds, explicit approvals, optional proof.
A9: Color key
A10: Blue | B10: Editable assumptions
A11: Green | B11: Sourced inputs / references
A12: Important: valuation sheet shows private ARR-multiple scenarios, not public market cap. | B12: Scenario-sensitive / review
A13: Runway is modeled from net burn after revenue using Y1 average assumptions and editable raise scenarios.
A14: Update the Assumptions sheet first; forecast, runway, valuation, and user-cost sheets recalculate from it.

Sheet Sources
A1: Source | B1: URL | C1: What used | D1: Date context
A2: Vercel pricing | B2: https://vercel.com/pricing | C2: Pro $20/mo, included credit, infrastructure pricing | D2: Crawled 2026-04-08
A3: Vercel plans | B3: https://vercel.com/docs/plans | C3: Plan behavior and spend management | D3: Docs updated 2026-01-07
A4: Supabase billing | B4: https://supabase.com/docs/guides/platform/billing-on-supabase | C4: Pro plan quotas and overages | D4: Crawled 2026-04-08
A5: Supabase MAU | B5: https://supabase.com/docs/guides/platform/manage-your-usage/monthly-active-users | C5: 100k MAU included, overage pricing | D5: Crawled 2026-04-08
A6: Supabase compute | B6: https://supabase.com/docs/guides/platform/manage-your-usage/compute | C6: Micro project compute and credits | D6: Crawled 2026-04-08
A7: Supabase storage | B7: https://supabase.com/docs/guides/storage/pricing | C7: Storage overage pricing | D7: Crawled 2026-04-08
A8: Supabase realtime | B8: https://supabase.com/docs/guides/realtime/pricing | C8: Realtime messages/connections pricing | D8: Crawled 2026-04-08
A9: Resend pricing | B9: https://resend.com/pricing | C9: Email plan pricing | D9: Crawled 2026-04-08
A10: FINMA FinTech | B10: https://www.finma.ch/en/authorisation/fintech/ | C10: Swiss legal perimeter reference | D10: Crawled 2026-04-08
A11: FINMA FinTech licence | B11: https://www.finma.ch/en/authorisation/fintech/fintech-bewilligung/ | C11: Deposit/yield boundary reference | D11: Crawled 2026-04-08
A12: FDPIC transfers | B12: https://www.edoeb.admin.ch/en/cross-border-transfer-of-personal-data | C12: Swiss privacy transfer reference | D12: Crawled 2026-04-08
A13: EU crypto-assets | B13: https://finance.ec.europa.eu/digital-finance/crypto-assets_en | C13: MiCA regulatory perimeter reference | D13: Crawled 2026-04-08

Sheet Assumptions
A1: Category | B1: Metric | C1: Today / Unit | D1: Y1 | E1: Y2 | F1: Y3 | G1: Y4 | H1: Y5
A2: Pricing
A3: Pricing | B3: Organizer Pro monthly price | C3: 12 | D3: 12 | E3: 12 | F3: 12 | G3: 12 | H3: 12
A4: Pricing | B4: Community / Club monthly price | C4: 49 | D4: 49 | E4: 49 | F4: 49 | G4: 49 | H4: 49
A5: Pricing | B5: SMB / Provider monthly price | C5: 149 | D5: 149 | E5: 149 | F5: 149 | G5: 149 | H5: 149
A6: Pricing | B6: Builder / API monthly price | C6: 499 | D6: 0 | E6: 0 | F6: 499 | G6: 499 | H6: 499
A7: Pricing | B7: Optional proof / closeout fee per month | C7: 0 | D7: 0 | E7: 0 | F7: 0 | G7: 0 | H7: 0
A8: Customer counts (average paying accounts in year)
A9: Counts | B9: Organizer Pro accounts | C9: 0 | D9: 250 | E9: 900 | F9: 2500 | G9: 6000 | H9: 12000
A10: Counts | B10: Community / Club accounts | C10: 0 | D10: 25 | E10: 90 | F10: 250 | G10: 600 | H10: 1200
A11: Counts | B11: SMB / Provider accounts | C11: 0 | D11: 5 | E11: 15 | F11: 50 | G11: 150 | H11: 300
A12: Counts | B12: Builder / API accounts | C12: 0 | D12: 0 | E12: 0 | F12: 5 | G12: 20 | H12: 60
A13: Counts | B13: Avg active users per paying account | C13: 4 | D13: 4 | E13: 4 | F13: 4 | G13: 4 | H13: 4
A14: Core vendor costs (monthly)
A15: Vendors | B15: Vercel Pro seat(s) cost | C15: 20 | D15: 20 | E15: 20 | F15: 20 | G15: 20 | H15: 20
A16: Vendors | B16: Supabase Pro org cost | C16: 25 | D16: 25 | E16: 25 | F16: 25 | G16: 25 | H16: 25
A17: Vendors | B17: Supabase extra compute / projects | C17: 10 | D17: 10 | E17: 20 | F17: 40 | G17: 80 | H17: 120
A18: Vendors | B18: Resend email cost | C18: 20 | D18: 20 | E18: 20 | F18: 20 | G18: 90 | H18: 90
A19: Vendors | B19: Monitoring / misc tools | C19: 35 | D19: 35 | E19: 50 | F19: 75 | G19: 100 | H19: 150
A20: Vendors | B20: Domains / DNS / workspace | C20: 15 | D20: 15 | E20: 20 | F20: 25 | G20: 30 | H20: 40
A21: Variable delivery assumptions
A22: Variable | B22: Variable platform cost per active user / month | C22: 0.05 | D22: 0.05 | E22: 0.05 | F22: 0.06 | G22: 0.07 | H22: 0.08
A23: Variable | B23: Payment / proof pass-through subsidized by ChopDot per paying account / month | C23: 0 | D23: 0 | E23: 0 | F23: 0.25 | G23: 0.5 | H23: 0.75
A24: People and overhead
A25: Salary | B25: Founder annual base salary | C25: 72000 | D25: 72000 | E25: 72000 | F25: 72000 | G25: 72000 | H25: 72000
A26: Salary | B26: Engineer annual base salary | C26: 120000 | D26: 120000 | E26: 120000 | F26: 125000 | G26: 130000 | H26: 135000
A27: Salary | B27: Product/Design annual base salary | C27: 100000 | D27: 100000 | E27: 105000 | F27: 110000 | G27: 115000 | H27: 120000
A28: Salary | B28: Ops/Compliance annual base salary | C28: 110000 | D28: 110000 | E28: 115000 | F28: 120000 | G28: 125000 | H28: 130000
A29: Salary | B29: Support/Community annual base salary | C29: 70000 | D29: 70000 | E29: 75000 | F29: 80000 | G29: 85000 | H29: 90000
A30: Headcount | B30: Founders | C30: 2 | D30: 2 | E30: 2 | F30: 2 | G30: 2 | H30: 2
A31: Headcount | B31: Engineering | C31: 0 | D31: 1 | E31: 2 | F31: 4 | G31: 6 | H31: 8
A32: Headcount | B32: Product/Design | C32: 0 | D32: 0 | E32: 1 | F32: 1 | G32: 2 | H32: 3
A33: Headcount | B33: Ops/Compliance | C33: 0 | D33: 0 | E33: 0 | F33: 1 | G33: 1 | H33: 2
A34: Headcount | B34: Support/Community | C34: 0 | D34: 0 | E34: 1 | F34: 1 | G34: 2 | H34: 4
A35: Overhead | B35: Employer tax / benefits rate | C35: 0.2 | D35: 0.2 | E35: 0.2 | F35: 0.2 | G35: 0.2 | H35: 0.2
A36: Operating expense assumptions
A37: Opex | B37: Legal / compliance monthly | C37: 1500 | D37: 1500 | E37: 2000 | F37: 3000 | G37: 5000 | H37: 8000
A38: Opex | B38: Accounting / finance monthly | C38: 300 | D38: 300 | E38: 500 | F38: 1000 | G38: 1500 | H38: 2500
A39: Opex | B39: Security review / tooling monthly | C39: 500 | D39: 500 | E39: 750 | F39: 1000 | G39: 1500 | H39: 2500
A40: Opex | B40: Marketing as % of revenue | C40: 0.1 | D40: 0.1 | E40: 0.12 | F40: 0.15 | G40: 0.18 | H40: 0.2
...

Sheet Today_Snapshot
A1: Metric | B1: Value
A2: Lean platform monthly cost | B2: =SUM(Assumptions!C15:C20)
A3: Governance / compliance monthly cost | B3: =SUM(Assumptions!C37:C39)
A4: Current monthly revenue run-rate (Y1 average) | B4: =Forecast_5Y!B6/12
A5: Full company monthly operating cost before revenue (Y1 average) | B5: =(Forecast_5Y!B8+Forecast_5Y!B9+SUM(Forecast_5Y!B11:B15))/12
A6: Current monthly net burn after revenue (Y1 average) | B6: =MAX(-Forecast_5Y!B16/12,0)
A7: Organizer Pro price / month | B7: =Assumptions!C3
A8: Community / Club price / month | B8: =Assumptions!C4
A9: SMB / Provider price / month | B9: =Assumptions!C5
A10: Builder / API price / month | B10: =Assumptions!C6
A11: Estimated Y1 ARR | B11: =Forecast_5Y!B6
A12: Estimated Y3 ARR | B12: =Forecast_5Y!D6
A13: Estimated Y5 ARR | B13: =Forecast_5Y!F6
A14: Estimated Y5 EBITDA | B14: =Forecast_5Y!F16
A15: Implied Y5 valuation (base multiple) | B15: =Valuation!D9
A16: Runway months with $500k raise | B16: =Runway!D7
A17: Runway months with $1.0m raise | B17: =Runway!E7

Sheet Forecast_5Y
A1: Metric | B1: Y1 | C1: Y2 | D1: Y3 | E1: Y4 | F1: Y5
A2: Organizer Pro revenue | B2: =12*Assumptions!D3*Assumptions!D9 | C2: =12*Assumptions!E3*Assumptions!E9 | D2: =12*Assumptions!F3*Assumptions!F9 | E2: =12*Assumptions!G3*Assumptions!G9 | F2: =12*Assumptions!H3*Assumptions!H9
A3: Community / Club revenue | B3: =12*Assumptions!D4*Assumptions!D10 | C3: =12*Assumptions!E4*Assumptions!E10 | D3: =12*Assumptions!F4*Assumptions!F10 | E3: =12*Assumptions!G4*Assumptions!G10 | F3: =12*Assumptions!H4*Assumptions!H10
A4: SMB / Provider revenue | B4: =12*Assumptions!D5*Assumptions!D11 | C4: =12*Assumptions!E5*Assumptions!E11 | D4: =12*Assumptions!F5*Assumptions!F11 | E4: =12*Assumptions!G5*Assumptions!G11 | F4: =12*Assumptions!H5*Assumptions!H11
A5: Builder / API revenue | B5: =12*Assumptions!D6*Assumptions!D12 | C5: =12*Assumptions!E6*Assumptions!E12 | D5: =12*Assumptions!F6*Assumptions!F12 | E5: =12*Assumptions!G6*Assumptions!G12 | F5: =12*Assumptions!H6*Assumptions!H12
A6: Total revenue | B6: =SUM(B2:B5) | C6: =SUM(C2:C5) | D6: =SUM(D2:D5) | E6: =SUM(E2:E5) | F6: =SUM(F2:F5)
A7: Active users | B7: =SUM(Assumptions!D9:Assumptions!D12)*Assumptions!D13 | C7: =SUM(Assumptions!E9:Assumptions!E12)*Assumptions!E13 | D7: =SUM(Assumptions!F9:Assumptions!F12)*Assumptions!F13 | E7: =SUM(Assumptions!G9:Assumptions!G12)*Assumptions!G13 | F7: =SUM(Assumptions!H9:Assumptions!H12)*Assumptions!H13
A8: Fixed platform cost | B8: =12*SUM(Assumptions!D15:Assumptions!D20) | C8: =12*SUM(Assumptions!E15:Assumptions!E20) | D8: =12*SUM(Assumptions!F15:Assumptions!F20) | E8: =12*SUM(Assumptions!G15:Assumptions!G20) | F8: =12*SUM(Assumptions!H15:Assumptions!H20)
A9: Variable platform cost | B9: =12*(B7*Assumptions!D22 + SUM(Assumptions!D9:Assumptions!D12)*Assumptions!D23) | C9: =12*(C7*Assumptions!E22 + SUM(Assumptions!E9:Assumptions!E12)*Assumptions!E23) | D9: =12*(D7*Assumptions!F22 + SUM(Assumptions!F9:Assumptions!F12)*Assumptions!F23) | E9: =12*(E7*Assumptions!G22 + SUM(Assumptions!G9:Assumptions!G12)*Assumptions!G23) | F9: =12*(F7*Assumptions!H22 + SUM(Assumptions!H9:Assumptions!H12)*Assumptions!H23)
A10: Gross profit | B10: =B6-B8-B9 | C10: =C6-C8-C9 | D10: =D6-D8-D9 | E10: =E6-E8-E9 | F10: =F6-F8-F9
A11: Payroll | B11: =(Assumptions!D25*Assumptions!D30+Assumptions!D26*Assumptions!D31+Assumptions!D27*Assumptions!D32+Assumptions!D28*Assumptions!D33+Assumptions!D29*Assumptions!D34)*(1+Assumptions!D35) | C11: =(Assumptions!E25*Assumptions!E30+Assumptions!E26*Assumptions!E31+Assumptions!E27*Assumptions!E32+Assumptions!E28*Assumptions!E33+Assumptions!E29*Assumptions!E34)*(1+Assumptions!E35) | D11: =(Assumptions!F25*Assumptions!F30+Assumptions!F26*Assumptions!F31+Assumptions!F27*Assumptions!F32+Assumptions!F28*Assumptions!F33+Assumptions!F29*Assumptions!F34)*(1+Assumptions!F35) | E11: =(Assumptions!G25*Assumptions!G30+Assumptions!G26*Assumptions!G31+Assumptions!G27*Assumptions!G32+Assumptions!G28*Assumptions!G33+Assumptions!G29*Assumptions!G34)*(1+Assumptions!G35) | F11: =(Assumptions!H25*Assumptions!H30+Assumptions!H26*Assumptions!H31+Assumptions!H27*Assumptions!H32+Assumptions!H28*Assumptions!H33+Assumptions!H29*Assumptions!H34)*(1+Assumptions!H35)
A12: Legal / compliance | B12: =12*Assumptions!D37 | C12: =12*Assumptions!E37 | D12: =12*Assumptions!F37 | E12: =12*Assumptions!G37 | F12: =12*Assumptions!H37
A13: Accounting / finance | B13: =12*Assumptions!D38 | C13: =12*Assumptions!E38 | D13: =12*Assumptions!F38 | E13: =12*Assumptions!G38 | F13: =12*Assumptions!H38
A14: Security review / tooling | B14: =12*Assumptions!D39 | C14: =12*Assumptions!E39 | D14: =12*Assumptions!F39 | E14: =12*Assumptions!G39 | F14: =12*Assumptions!H39
A15: Marketing | B15: =MAX(12*Assumptions!D41,B6*Assumptions!D40) | C15: =MAX(12*Assumptions!E41,C6*Assumptions!E40) | D15: =MAX(12*Assumptions!F41,D6*Assumptions!F40) | E15: =MAX(12*Assumptions!G41,E6*Assumptions!G40) | F15: =MAX(12*Assumptions!H41,F6*Assumptions!H40)
A16: EBITDA | B16: =B10-SUM(B11:B15) | C16: =C10-SUM(C11:C15) | D16: =D10-SUM(D11:D15) | E16: =E10-SUM(E11:E15) | F16: =F10-SUM(F11:F15)
A17: EBITDA margin | B17: =IF(B6=0,0,B16/B6) | C17: =IF(C6=0,0,C16/C6) | D17: =IF(D6=0,0,D16/D6) | E17: =IF(E6=0,0,E16/E6) | F17: =IF(F6=0,0,F16/F6)

Sheet Runway
A1: Metric | B1: Today | C1: Raise A | D1: Raise B | E1: Raise C
A2: Current monthly platform cost | B2: =Today_Snapshot!B2
A3: Current monthly governance / compliance cost | B3: =Today_Snapshot!B3
A4: Current monthly revenue run-rate | B4: =Today_Snapshot!B4
A5: Current monthly operating cost before revenue | B5: =Today_Snapshot!B5
A6: Current monthly net burn after revenue | B6: =Today_Snapshot!B6
A7: Runway months | B7: =IF($B$6=0,0,Assumptions!C43/$B$6) | C7: =IF($B$6=0,0,Assumptions!C44/$B$6) | D7: =IF($B$6=0,0,Assumptions!C45/$B$6) | E7: =IF($B$6=0,0,Assumptions!C46/$B$6)
A8: Interpretation
A9: Raise A = small pre-seed buffer
A10: Raise B = realistic pre-seed / angel round
A11: Raise C = larger seed runway case

Sheet Valuation
A1: Metric | B1: Y3 | C1: Y4 | D1: Y5
A2: ARR | B2: =Forecast_5Y!D6 | C2: =Forecast_5Y!E6 | D2: =Forecast_5Y!F6
A4: Low multiple | B4: =Assumptions!F47 | C4: =Assumptions!G47 | D4: =Assumptions!H47
A5: Base multiple | B5: =Assumptions!F48 | C5: =Assumptions!G48 | D5: =Assumptions!H48
A6: High multiple | B6: =Assumptions!F49 | C6: =Assumptions!G49 | D6: =Assumptions!H49
A8: Implied valuation (low) | B8: =B2*B4 | C8: =C2*C4 | D8: =D2*D4
A9: Implied valuation (base) | B9: =B2*B5 | C9: =C2*C5 | D9: =D2*D5
A10: Implied valuation (high) | B10: =B2*B6 | C10: =C2*C6 | D10: =D2*D6
A12: Note | B12: Private ARR multiple scenarios, not public market cap

Sheet User_Costs
A1: Metric | B1: Today answer
A2: Participant cost to use ChopDot | B2: $0 base software cost if included in an organizer account
A3: Organizer Pro cost | B3: =TEXT(Assumptions!C3,"$0") & "/mo"
A4: Community / Club cost | B4: =TEXT(Assumptions!C4,"$0") & "/mo"
A5: SMB / Provider cost | B5: =TEXT(Assumptions!C5,"$0") & "/mo"
A6: Optional external rail cost | B6: Bank/card/onchain fees passed through at cost; not modeled as ChopDot revenue today
A7: Effective cost per member in 4-person Organizer Pro group | B7: =TEXT(Assumptions!C3/Assumptions!C13,"$0.00") & "/mo"
